2018-11-14 17:03:55,540 INFO: Microblog startup [in D:\PY_Works\F_Project\mblog\microblog\app\__init__.py:48]
2018-11-14 17:07:30,256 ERROR: Exception on /edit_profile [POST] [in d:\py_works\f_project\mblog\microblog\venv\lib\site-packages\flask\app.py:1761]
Traceback (most recent call last):
  File "d:\py_works\f_project\mblog\microblog\venv\lib\site-packages\sqlalchemy\engine\base.py", line 1193, in _execute_context
    context)
  File "d:\py_works\f_project\mblog\microblog\venv\lib\site-packages\sqlalchemy\engine\default.py", line 509, in do_execute
    cursor.execute(statement, parameters)
sqlite3.IntegrityError: UNIQUE constraint failed: user.username

The above exception was the direct cause of the following exception:

Traceback (most recent call last):
  File "d:\py_works\f_project\mblog\microblog\venv\lib\site-packages\flask\app.py", line 2292, in wsgi_app
    response = self.full_dispatch_request()
  File "d:\py_works\f_project\mblog\microblog\venv\lib\site-packages\flask\app.py", line 1815, in full_dispatch_request
    rv = self.handle_user_exception(e)
  File "d:\py_works\f_project\mblog\microblog\venv\lib\site-packages\flask\app.py", line 1718, in handle_user_exception
    reraise(exc_type, exc_value, tb)
  File "d:\py_works\f_project\mblog\microblog\venv\lib\site-packages\flask\_compat.py", line 35, in reraise
    raise value
  File "d:\py_works\f_project\mblog\microblog\venv\lib\site-packages\flask\app.py", line 1813, in full_dispatch_request
    rv = self.dispatch_request()
  File "d:\py_works\f_project\mblog\microblog\venv\lib\site-packages\flask\app.py", line 1799, in dispatch_request
    return self.view_functions[rule.endpoint](**req.view_args)
  File "d:\py_works\f_project\mblog\microblog\venv\lib\site-packages\flask_login\utils.py", line 261, in decorated_view
    return func(*args, **kwargs)
  File "D:\PY_Works\F_Project\mblog\microblog\app\routes.py", line 90, in edit_profile
    db.session.commit()
  File "d:\py_works\f_project\mblog\microblog\venv\lib\site-packages\sqlalchemy\orm\scoping.py", line 153, in do
    return getattr(self.registry(), name)(*args, **kwargs)
  File "d:\py_works\f_project\mblog\microblog\venv\lib\site-packages\sqlalchemy\orm\session.py", line 954, in commit
    self.transaction.commit()
  File "d:\py_works\f_project\mblog\microblog\venv\lib\site-packages\sqlalchemy\orm\session.py", line 467, in commit
    self._prepare_impl()
  File "d:\py_works\f_project\mblog\microblog\venv\lib\site-packages\sqlalchemy\orm\session.py", line 447, in _prepare_impl
    self.session.flush()
  File "d:\py_works\f_project\mblog\microblog\venv\lib\site-packages\sqlalchemy\orm\session.py", line 2313, in flush
    self._flush(objects)
  File "d:\py_works\f_project\mblog\microblog\venv\lib\site-packages\sqlalchemy\orm\session.py", line 2440, in _flush
    transaction.rollback(_capture_exception=True)
  File "d:\py_works\f_project\mblog\microblog\venv\lib\site-packages\sqlalchemy\util\langhelpers.py", line 66, in __exit__
    compat.reraise(exc_type, exc_value, exc_tb)
  File "d:\py_works\f_project\mblog\microblog\venv\lib\site-packages\sqlalchemy\util\compat.py", line 249, in reraise
    raise value
  File "d:\py_works\f_project\mblog\microblog\venv\lib\site-packages\sqlalchemy\orm\session.py", line 2404, in _flush
    flush_context.execute()
  File "d:\py_works\f_project\mblog\microblog\venv\lib\site-packages\sqlalchemy\orm\unitofwork.py", line 395, in execute
    rec.execute(self)
  File "d:\py_works\f_project\mblog\microblog\venv\lib\site-packages\sqlalchemy\orm\unitofwork.py", line 560, in execute
    uow
  File "d:\py_works\f_project\mblog\microblog\venv\lib\site-packages\sqlalchemy\orm\persistence.py", line 177, in save_obj
    mapper, table, update)
  File "d:\py_works\f_project\mblog\microblog\venv\lib\site-packages\sqlalchemy\orm\persistence.py", line 774, in _emit_update_statements
    execute(statement, multiparams)
  File "d:\py_works\f_project\mblog\microblog\venv\lib\site-packages\sqlalchemy\engine\base.py", line 948, in execute
    return meth(self, multiparams, params)
  File "d:\py_works\f_project\mblog\microblog\venv\lib\site-packages\sqlalchemy\sql\elements.py", line 269, in _execute_on_connection
    return connection._execute_clauseelement(self, multiparams, params)
  File "d:\py_works\f_project\mblog\microblog\venv\lib\site-packages\sqlalchemy\engine\base.py", line 1060, in _execute_clauseelement
    compiled_sql, distilled_params
  File "d:\py_works\f_project\mblog\microblog\venv\lib\site-packages\sqlalchemy\engine\base.py", line 1200, in _execute_context
    context)
  File "d:\py_works\f_project\mblog\microblog\venv\lib\site-packages\sqlalchemy\engine\base.py", line 1413, in _handle_dbapi_exception
    exc_info
  File "d:\py_works\f_project\mblog\microblog\venv\lib\site-packages\sqlalchemy\util\compat.py", line 265, in raise_from_cause
    reraise(type(exception), exception, tb=exc_tb, cause=cause)
  File "d:\py_works\f_project\mblog\microblog\venv\lib\site-packages\sqlalchemy\util\compat.py", line 248, in reraise
    raise value.with_traceback(tb)
  File "d:\py_works\f_project\mblog\microblog\venv\lib\site-packages\sqlalchemy\engine\base.py", line 1193, in _execute_context
    context)
  File "d:\py_works\f_project\mblog\microblog\venv\lib\site-packages\sqlalchemy\engine\default.py", line 509, in do_execute
    cursor.execute(statement, parameters)
sqlalchemy.exc.IntegrityError: (sqlite3.IntegrityError) UNIQUE constraint failed: user.username [SQL: 'UPDATE user SET username=?, about_me=? WHERE user.id = ?'] [parameters: ('Nitesh', '', 4)] (Background on this error at: http://sqlalche.me/e/gkpj)
2018-11-14 17:14:41,676 INFO: Microblog startup [in D:\PY_Works\F_Project\mblog\microblog\app\__init__.py:48]
2018-11-14 17:47:44,505 INFO: Microblog startup [in D:\PY_Works\F_Project\mblog\microblog\app\__init__.py:48]
2018-11-14 17:47:54,813 INFO: Microblog startup [in D:\PY_Works\F_Project\mblog\microblog\app\__init__.py:48]
2018-11-14 18:19:20,009 INFO: Microblog startup [in D:\PY_Works\F_Project\mblog\microblog\app\__init__.py:48]
2018-11-16 12:36:22,938 INFO: Microblog startup [in D:\PY_Works\F_Project\mblog\microblog\app\__init__.py:48]
2018-11-16 12:36:52,295 ERROR: Exception on / [GET] [in d:\py_works\f_project\mblog\microblog\venv\lib\site-packages\flask\app.py:1761]
Traceback (most recent call last):
  File "d:\py_works\f_project\mblog\microblog\venv\lib\site-packages\flask\app.py", line 2292, in wsgi_app
    response = self.full_dispatch_request()
  File "d:\py_works\f_project\mblog\microblog\venv\lib\site-packages\flask\app.py", line 1815, in full_dispatch_request
    rv = self.handle_user_exception(e)
  File "d:\py_works\f_project\mblog\microblog\venv\lib\site-packages\flask\app.py", line 1718, in handle_user_exception
    reraise(exc_type, exc_value, tb)
  File "d:\py_works\f_project\mblog\microblog\venv\lib\site-packages\flask\_compat.py", line 35, in reraise
    raise value
  File "d:\py_works\f_project\mblog\microblog\venv\lib\site-packages\flask\app.py", line 1813, in full_dispatch_request
    rv = self.dispatch_request()
  File "d:\py_works\f_project\mblog\microblog\venv\lib\site-packages\flask\app.py", line 1799, in dispatch_request
    return self.view_functions[rule.endpoint](**req.view_args)
  File "d:\py_works\f_project\mblog\microblog\venv\lib\site-packages\flask_login\utils.py", line 261, in decorated_view
    return func(*args, **kwargs)
  File "D:\PY_Works\F_Project\mblog\microblog\app\routes.py", line 25, in index
    return render_template('index.html' ,title = "Home" ,posts = posts)
  File "d:\py_works\f_project\mblog\microblog\venv\lib\site-packages\flask\templating.py", line 135, in render_template
    context, ctx.app)
  File "d:\py_works\f_project\mblog\microblog\venv\lib\site-packages\flask\templating.py", line 117, in _render
    rv = template.render(context)
  File "d:\py_works\f_project\mblog\microblog\venv\lib\site-packages\jinja2\asyncsupport.py", line 76, in render
    return original_render(self, *args, **kwargs)
  File "d:\py_works\f_project\mblog\microblog\venv\lib\site-packages\jinja2\environment.py", line 1008, in render
    return self.environment.handle_exception(exc_info, True)
  File "d:\py_works\f_project\mblog\microblog\venv\lib\site-packages\jinja2\environment.py", line 780, in handle_exception
    reraise(exc_type, exc_value, tb)
  File "d:\py_works\f_project\mblog\microblog\venv\lib\site-packages\jinja2\_compat.py", line 37, in reraise
    raise value.with_traceback(tb)
  File "D:\PY_Works\F_Project\mblog\microblog\app\templates\index.html", line 1, in top-level template code
    {% extends "base.html" %}
  File "D:\PY_Works\F_Project\mblog\microblog\app\templates\base.html", line 14, in top-level template code
    <a href="{{ url_for('user') }}">Profile</a>
  File "d:\py_works\f_project\mblog\microblog\venv\lib\site-packages\flask\helpers.py", line 356, in url_for
    return appctx.app.handle_url_build_error(error, endpoint, values)
  File "d:\py_works\f_project\mblog\microblog\venv\lib\site-packages\flask\app.py", line 2061, in handle_url_build_error
    reraise(exc_type, exc_value, tb)
  File "d:\py_works\f_project\mblog\microblog\venv\lib\site-packages\flask\_compat.py", line 35, in reraise
    raise value
  File "d:\py_works\f_project\mblog\microblog\venv\lib\site-packages\flask\helpers.py", line 345, in url_for
    force_external=external)
  File "d:\py_works\f_project\mblog\microblog\venv\lib\site-packages\werkzeug\routing.py", line 1776, in build
    raise BuildError(endpoint, values, method, self)
werkzeug.routing.BuildError: Could not build url for endpoint 'user'. Did you forget to specify values ['username']?
2018-11-16 12:38:54,932 INFO: Microblog startup [in D:\PY_Works\F_Project\mblog\microblog\app\__init__.py:48]
