2018-11-16 12:38:58,256 ERROR: Exception on / [GET] [in d:\py_works\f_project\mblog\microblog\venv\lib\site-packages\flask\app.py:1761]
Traceback (most recent call last):
  File "d:\py_works\f_project\mblog\microblog\venv\lib\site-packages\flask\app.py", line 2292, in wsgi_app
    response = self.full_dispatch_request()
  File "d:\py_works\f_project\mblog\microblog\venv\lib\site-packages\flask\app.py", line 1815, in full_dispatch_request
    rv = self.handle_user_exception(e)
  File "d:\py_works\f_project\mblog\microblog\venv\lib\site-packages\flask\app.py", line 1718, in handle_user_exception
    reraise(exc_type, exc_value, tb)
  File "d:\py_works\f_project\mblog\microblog\venv\lib\site-packages\flask\_compat.py", line 35, in reraise
    raise value
  File "d:\py_works\f_project\mblog\microblog\venv\lib\site-packages\flask\app.py", line 1813, in full_dispatch_request
    rv = self.dispatch_request()
  File "d:\py_works\f_project\mblog\microblog\venv\lib\site-packages\flask\app.py", line 1799, in dispatch_request
    return self.view_functions[rule.endpoint](**req.view_args)
  File "d:\py_works\f_project\mblog\microblog\venv\lib\site-packages\flask_login\utils.py", line 261, in decorated_view
    return func(*args, **kwargs)
  File "D:\PY_Works\F_Project\mblog\microblog\app\routes.py", line 25, in index
    return render_template('index.html' ,title = "Home" ,posts = posts)
  File "d:\py_works\f_project\mblog\microblog\venv\lib\site-packages\flask\templating.py", line 135, in render_template
    context, ctx.app)
  File "d:\py_works\f_project\mblog\microblog\venv\lib\site-packages\flask\templating.py", line 117, in _render
    rv = template.render(context)
  File "d:\py_works\f_project\mblog\microblog\venv\lib\site-packages\jinja2\asyncsupport.py", line 76, in render
    return original_render(self, *args, **kwargs)
  File "d:\py_works\f_project\mblog\microblog\venv\lib\site-packages\jinja2\environment.py", line 1008, in render
    return self.environment.handle_exception(exc_info, True)
  File "d:\py_works\f_project\mblog\microblog\venv\lib\site-packages\jinja2\environment.py", line 780, in handle_exception
    reraise(exc_type, exc_value, tb)
  File "d:\py_works\f_project\mblog\microblog\venv\lib\site-packages\jinja2\_compat.py", line 37, in reraise
    raise value.with_traceback(tb)
  File "D:\PY_Works\F_Project\mblog\microblog\app\templates\index.html", line 1, in top-level template code
    {% extends "base.html" %}
  File "D:\PY_Works\F_Project\mblog\microblog\app\templates\base.html", line 14, in top-level template code
    <a href="{{ url_for('user' , current_user.username) }}">Profile</a>
TypeError: url_for() takes 1 positional argument but 2 were given
2018-11-16 12:39:38,945 INFO: Microblog startup [in D:\PY_Works\F_Project\mblog\microblog\app\__init__.py:48]
2018-11-20 11:53:02,798 INFO: Microblog startup [in D:\PY_Works\F_Project\mblog\microblog\app\__init__.py:48]
2018-11-20 11:54:01,050 INFO: Microblog startup [in D:\PY_Works\F_Project\mblog\microblog\app\__init__.py:48]
2018-11-20 11:55:56,738 INFO: Microblog startup [in D:\PY_Works\F_Project\mblog\microblog\app\__init__.py:48]
2018-11-20 11:58:53,010 ERROR: Exception on /login [POST] [in d:\py_works\f_project\mblog\microblog\venv\lib\site-packages\flask\app.py:1761]
Traceback (most recent call last):
  File "d:\py_works\f_project\mblog\microblog\venv\lib\site-packages\flask\app.py", line 2292, in wsgi_app
    response = self.full_dispatch_request()
  File "d:\py_works\f_project\mblog\microblog\venv\lib\site-packages\flask\app.py", line 1815, in full_dispatch_request
    rv = self.handle_user_exception(e)
  File "d:\py_works\f_project\mblog\microblog\venv\lib\site-packages\flask\app.py", line 1718, in handle_user_exception
    reraise(exc_type, exc_value, tb)
  File "d:\py_works\f_project\mblog\microblog\venv\lib\site-packages\flask\_compat.py", line 35, in reraise
    raise value
  File "d:\py_works\f_project\mblog\microblog\venv\lib\site-packages\flask\app.py", line 1813, in full_dispatch_request
    rv = self.dispatch_request()
  File "d:\py_works\f_project\mblog\microblog\venv\lib\site-packages\flask\app.py", line 1799, in dispatch_request
    return self.view_functions[rule.endpoint](**req.view_args)
  File "D:\PY_Works\F_Project\mblog\microblog\app\routes.py", line 33, in login
    if user is None or not user.check_password(form.password.data):
  File "D:\PY_Works\F_Project\mblog\microblog\app\models.py", line 32, in check_password
    return check_password_hash(self.password_hash, password)
  File "d:\py_works\f_project\mblog\microblog\venv\lib\site-packages\werkzeug\security.py", line 245, in check_password_hash
    if pwhash.count('$') < 2:
AttributeError: 'NoneType' object has no attribute 'count'
2018-11-20 13:44:44,885 INFO: Microblog startup [in D:\PY_Works\F_Project\mblog\microblog\app\__init__.py:48]
2018-11-20 15:06:09,040 INFO: Microblog startup [in D:\PY_Works\F_Project\mblog\microblog\app\__init__.py:48]
2018-11-20 15:07:00,143 INFO: Microblog startup [in D:\PY_Works\F_Project\mblog\microblog\app\__init__.py:48]
2018-11-20 15:10:16,910 INFO: Microblog startup [in D:\PY_Works\F_Project\mblog\microblog\app\__init__.py:48]
2018-11-20 15:10:19,213 ERROR: Exception on /user/Nitesh [GET] [in d:\py_works\f_project\mblog\microblog\venv\lib\site-packages\flask\app.py:1761]
Traceback (most recent call last):
  File "d:\py_works\f_project\mblog\microblog\venv\lib\site-packages\flask\app.py", line 2292, in wsgi_app
    response = self.full_dispatch_request()
  File "d:\py_works\f_project\mblog\microblog\venv\lib\site-packages\flask\app.py", line 1815, in full_dispatch_request
    rv = self.handle_user_exception(e)
  File "d:\py_works\f_project\mblog\microblog\venv\lib\site-packages\flask\app.py", line 1718, in handle_user_exception
    reraise(exc_type, exc_value, tb)
  File "d:\py_works\f_project\mblog\microblog\venv\lib\site-packages\flask\_compat.py", line 35, in reraise
    raise value
  File "d:\py_works\f_project\mblog\microblog\venv\lib\site-packages\flask\app.py", line 1813, in full_dispatch_request
    rv = self.dispatch_request()
  File "d:\py_works\f_project\mblog\microblog\venv\lib\site-packages\flask\app.py", line 1799, in dispatch_request
    return self.view_functions[rule.endpoint](**req.view_args)
  File "d:\py_works\f_project\mblog\microblog\venv\lib\site-packages\flask_login\utils.py", line 261, in decorated_view
    return func(*args, **kwargs)
  File "D:\PY_Works\F_Project\mblog\microblog\app\routes.py", line 93, in user
    return render_template("user.html" , user = user , posts = posts)
  File "d:\py_works\f_project\mblog\microblog\venv\lib\site-packages\flask\templating.py", line 135, in render_template
    context, ctx.app)
  File "d:\py_works\f_project\mblog\microblog\venv\lib\site-packages\flask\templating.py", line 117, in _render
    rv = template.render(context)
  File "d:\py_works\f_project\mblog\microblog\venv\lib\site-packages\jinja2\asyncsupport.py", line 76, in render
    return original_render(self, *args, **kwargs)
  File "d:\py_works\f_project\mblog\microblog\venv\lib\site-packages\jinja2\environment.py", line 1008, in render
    return self.environment.handle_exception(exc_info, True)
  File "d:\py_works\f_project\mblog\microblog\venv\lib\site-packages\jinja2\environment.py", line 780, in handle_exception
    reraise(exc_type, exc_value, tb)
  File "d:\py_works\f_project\mblog\microblog\venv\lib\site-packages\jinja2\_compat.py", line 37, in reraise
    raise value.with_traceback(tb)
  File "D:\PY_Works\F_Project\mblog\microblog\app\templates\user.html", line 1, in top-level template code
    {% extends "base.html" %}
  File "D:\PY_Works\F_Project\mblog\microblog\app\templates\base.html", line 29, in top-level template code
    {% block content %}{% endblock %}
  File "D:\PY_Works\F_Project\mblog\microblog\app\templates\user.html", line 23, in block "content"
    {% for post in posts: %}
TypeError: 'Pagination' object is not iterable
